<?xml version="1.0" encoding="UTF-8"?>
<testng-results skipped="0" failed="2" ignored="0" total="4" passed="2">
  <reporter-output>
  </reporter-output>
  <suite name="All Test Suite" duration-ms="7" started-at="2021-10-19T08:15:42Z" finished-at="2021-10-19T08:15:42Z">
    <groups>
    </groups>
    <test name="/Users/zc/IdeaProjects/NewCRUD/src/test/java/com/newcrud" duration-ms="7" started-at="2021-10-19T08:15:42Z" finished-at="2021-10-19T08:15:42Z">
      <class name="com.newcrud.testngTest.TestFour">
        <test-method status="FAIL" signature="testA()[pri:0, instance:com.newcrud.testngTest.TestFour@22ebccb9]" name="testA" duration-ms="0" started-at="2021-10-19T16:15:42Z" finished-at="2021-10-19T16:15:42Z">
          <exception class="java.lang.AssertionError">
            <message>
              <![CDATA[expected [2] but found [1]]]>
            </message>
            <full-stacktrace>
              <![CDATA[java.lang.AssertionError: expected [2] but found [1]
	at org.testng.Assert.fail(Assert.java:94)
	at org.testng.Assert.failNotEquals(Assert.java:513)
	at org.testng.Assert.assertEqualsImpl(Assert.java:135)
	at org.testng.Assert.assertEquals(Assert.java:116)
	at org.testng.Assert.assertEquals(Assert.java:389)
	at org.testng.Assert.assertEquals(Assert.java:399)
	at com.newcrud.testngTest.TestFour.testA(TestFour.java:9)
	at sun.reflect.NativeMethodAccessorImpl.invoke0(Native Method)
	at sun.reflect.NativeMethodAccessorImpl.invoke(NativeMethodAccessorImpl.java:62)
	at sun.reflect.DelegatingMethodAccessorImpl.invoke(DelegatingMethodAccessorImpl.java:43)
	at java.lang.reflect.Method.invoke(Method.java:498)
	at org.testng.internal.MethodInvocationHelper.invokeMethod(MethodInvocationHelper.java:104)
	at org.testng.internal.InvokeMethodRunnable.runOne(InvokeMethodRunnable.java:54)
	at org.testng.internal.InvokeMethodRunnable.run(InvokeMethodRunnable.java:44)
	at java.util.concurrent.Executors$RunnableAdapter.call(Executors.java:511)
	at java.util.concurrent.FutureTask.run(FutureTask.java:266)
	at java.util.concurrent.ThreadPoolExecutor.runWorker(ThreadPoolExecutor.java:1149)
	at java.util.concurrent.ThreadPoolExecutor$Worker.run(ThreadPoolExecutor.java:624)
	at java.lang.Thread.run(Thread.java:748)
]]>
            </full-stacktrace>
          </exception> <!-- java.lang.AssertionError -->
          <reporter-output>
          </reporter-output>
        </test-method> <!-- testA -->
        <test-method status="PASS" signature="testB()[pri:0, instance:com.newcrud.testngTest.TestFour@22ebccb9]" name="testB" duration-ms="1" started-at="2021-10-19T16:15:42Z" finished-at="2021-10-19T16:15:42Z">
          <reporter-output>
          </reporter-output>
        </test-method> <!-- testB -->
      </class> <!-- com.newcrud.testngTest.TestFour -->
      <class name="com.newcrud.testngTest.TestThree">
        <test-method status="FAIL" signature="testA()[pri:0, instance:com.newcrud.testngTest.TestThree@354e7004]" name="testA" duration-ms="3" started-at="2021-10-19T16:15:42Z" finished-at="2021-10-19T16:15:42Z">
          <exception class="java.lang.AssertionError">
            <message>
              <![CDATA[expected [2] but found [1]]]>
            </message>
            <full-stacktrace>
              <![CDATA[java.lang.AssertionError: expected [2] but found [1]
	at org.testng.Assert.fail(Assert.java:94)
	at org.testng.Assert.failNotEquals(Assert.java:513)
	at org.testng.Assert.assertEqualsImpl(Assert.java:135)
	at org.testng.Assert.assertEquals(Assert.java:116)
	at org.testng.Assert.assertEquals(Assert.java:389)
	at org.testng.Assert.assertEquals(Assert.java:399)
	at com.newcrud.testngTest.TestThree.testA(TestThree.java:10)
	at sun.reflect.NativeMethodAccessorImpl.invoke0(Native Method)
	at sun.reflect.NativeMethodAccessorImpl.invoke(NativeMethodAccessorImpl.java:62)
	at sun.reflect.DelegatingMethodAccessorImpl.invoke(DelegatingMethodAccessorImpl.java:43)
	at java.lang.reflect.Method.invoke(Method.java:498)
	at org.testng.internal.MethodInvocationHelper.invokeMethod(MethodInvocationHelper.java:104)
	at org.testng.internal.InvokeMethodRunnable.runOne(InvokeMethodRunnable.java:54)
	at org.testng.internal.InvokeMethodRunnable.run(InvokeMethodRunnable.java:44)
	at java.util.concurrent.Executors$RunnableAdapter.call(Executors.java:511)
	at java.util.concurrent.FutureTask.run(FutureTask.java:266)
	at java.util.concurrent.ThreadPoolExecutor.runWorker(ThreadPoolExecutor.java:1149)
	at java.util.concurrent.ThreadPoolExecutor$Worker.run(ThreadPoolExecutor.java:624)
	at java.lang.Thread.run(Thread.java:748)
]]>
            </full-stacktrace>
          </exception> <!-- java.lang.AssertionError -->
          <reporter-output>
          </reporter-output>
        </test-method> <!-- testA -->
        <test-method status="PASS" signature="testB()[pri:0, instance:com.newcrud.testngTest.TestThree@354e7004]" name="testB" duration-ms="0" started-at="2021-10-19T16:15:42Z" finished-at="2021-10-19T16:15:42Z">
          <reporter-output>
          </reporter-output>
        </test-method> <!-- testB -->
      </class> <!-- com.newcrud.testngTest.TestThree -->
    </test> <!-- /Users/zc/IdeaProjects/NewCRUD/src/test/java/com/newcrud -->
  </suite> <!-- All Test Suite -->
</testng-results>
