<?xml version="1.0" encoding="UTF-8"?>
<!-- Generated by org.testng.reporters.JUnitReportReporter -->
<testsuite name="com.newcrud.testngTest.TestThree" tests="2" time="0.003" ignored="0" failures="1" timestamp="19 十月 2021 08:15:42 GMT" skipped="0" hostname="ZHR.local" errors="0">
  <testcase name="testA" time="0.003" classname="com.newcrud.testngTest.TestThree">
    <failure type="java.lang.AssertionError" message="expected [2] but found [1]">
      <![CDATA[java.lang.AssertionError: expected [2] but found [1]
	at org.testng.Assert.fail(Assert.java:94)
	at org.testng.Assert.failNotEquals(Assert.java:513)
	at org.testng.Assert.assertEqualsImpl(Assert.java:135)
	at org.testng.Assert.assertEquals(Assert.java:116)
	at org.testng.Assert.assertEquals(Assert.java:389)
	at org.testng.Assert.assertEquals(Assert.java:399)
	at com.newcrud.testngTest.TestThree.testA(TestThree.java:10)
	at sun.reflect.NativeMethodAccessorImpl.invoke0(Native Method)
	at sun.reflect.NativeMethodAccessorImpl.invoke(NativeMethodAccessorImpl.java:62)
	at sun.reflect.DelegatingMethodAccessorImpl.invoke(DelegatingMethodAccessorImpl.java:43)
	at java.lang.reflect.Method.invoke(Method.java:498)
	at org.testng.internal.MethodInvocationHelper.invokeMethod(MethodInvocationHelper.java:104)
	at org.testng.internal.InvokeMethodRunnable.runOne(InvokeMethodRunnable.java:54)
	at org.testng.internal.InvokeMethodRunnable.run(InvokeMethodRunnable.java:44)
	at java.util.concurrent.Executors$RunnableAdapter.call(Executors.java:511)
	at java.util.concurrent.FutureTask.run(FutureTask.java:266)
	at java.util.concurrent.ThreadPoolExecutor.runWorker(ThreadPoolExecutor.java:1149)
	at java.util.concurrent.ThreadPoolExecutor$Worker.run(ThreadPoolExecutor.java:624)
	at java.lang.Thread.run(Thread.java:748)
]]>
    </failure>
  </testcase> <!-- testA -->
  <testcase name="testB" time="0.000" classname="com.newcrud.testngTest.TestThree"/>
</testsuite> <!-- com.newcrud.testngTest.TestThree -->
